Exception in Tkinter callback
Traceback (most recent call last):
  File "/home/franzhd/anaconda3/envs/lava_new/lib/python3.9/tkinter/__init__.py", line 1892, in __call__
    return self.func(*args)
  File "/home/franzhd/anaconda3/envs/lava_new/lib/python3.9/tkinter/__init__.py", line 814, in callit
    func(*args)
  File "/home/franzhd/anaconda3/envs/lava_new/lib/python3.9/site-packages/matplotlib/backends/_backend_tk.py", line 252, in idle_draw
    self.draw()
  File "/home/franzhd/anaconda3/envs/lava_new/lib/python3.9/site-packages/matplotlib/backends/backend_tkagg.py", line 9, in draw
    super().draw()
  File "/home/franzhd/anaconda3/envs/lava_new/lib/python3.9/site-packages/matplotlib/backends/backend_agg.py", line 436, in draw
    self.figure.draw(self.renderer)
  File "/home/franzhd/anaconda3/envs/lava_new/lib/python3.9/site-packages/matplotlib/artist.py", line 73, in draw_wrapper
    result = draw(artist, renderer, *args, **kwargs)
  File "/home/franzhd/anaconda3/envs/lava_new/lib/python3.9/site-packages/matplotlib/artist.py", line 50, in draw_wrapper
    return draw(artist, renderer)
  File "/home/franzhd/anaconda3/envs/lava_new/lib/python3.9/site-packages/matplotlib/figure.py", line 2847, in draw
    self.canvas.draw_event(renderer)
  File "/home/franzhd/anaconda3/envs/lava_new/lib/python3.9/site-packages/matplotlib/backend_bases.py", line 1779, in draw_event
    self.callbacks.process(s, event)
  File "/home/franzhd/anaconda3/envs/lava_new/lib/python3.9/site-packages/matplotlib/cbook/__init__.py", line 292, in process
    self.exception_handler(exc)
  File "/home/franzhd/anaconda3/envs/lava_new/lib/python3.9/site-packages/matplotlib/cbook/__init__.py", line 96, in _exception_printer
    raise exc
  File "/home/franzhd/anaconda3/envs/lava_new/lib/python3.9/site-packages/matplotlib/cbook/__init__.py", line 287, in process
    func(*args, **kwargs)
  File "/home/franzhd/anaconda3/envs/lava_new/lib/python3.9/site-packages/matplotlib/animation.py", line 911, in _start
    self.event_source.add_callback(self._step)
AttributeError: 'NoneType' object has no attribute 'add_callback'
Exception in Tkinter callback
Traceback (most recent call last):
  File "/home/franzhd/anaconda3/envs/lava_new/lib/python3.9/tkinter/__init__.py", line 1892, in __call__
    return self.func(*args)
  File "/home/franzhd/anaconda3/envs/lava_new/lib/python3.9/tkinter/__init__.py", line 814, in callit
    func(*args)
  File "/home/franzhd/anaconda3/envs/lava_new/lib/python3.9/site-packages/matplotlib/backends/_backend_tk.py", line 252, in idle_draw
    self.draw()
  File "/home/franzhd/anaconda3/envs/lava_new/lib/python3.9/site-packages/matplotlib/backends/backend_tkagg.py", line 9, in draw
    super().draw()
  File "/home/franzhd/anaconda3/envs/lava_new/lib/python3.9/site-packages/matplotlib/backends/backend_agg.py", line 436, in draw
    self.figure.draw(self.renderer)
  File "/home/franzhd/anaconda3/envs/lava_new/lib/python3.9/site-packages/matplotlib/artist.py", line 73, in draw_wrapper
    result = draw(artist, renderer, *args, **kwargs)
  File "/home/franzhd/anaconda3/envs/lava_new/lib/python3.9/site-packages/matplotlib/artist.py", line 50, in draw_wrapper
    return draw(artist, renderer)
  File "/home/franzhd/anaconda3/envs/lava_new/lib/python3.9/site-packages/matplotlib/figure.py", line 2847, in draw
    self.canvas.draw_event(renderer)
  File "/home/franzhd/anaconda3/envs/lava_new/lib/python3.9/site-packages/matplotlib/backend_bases.py", line 1779, in draw_event
    self.callbacks.process(s, event)
  File "/home/franzhd/anaconda3/envs/lava_new/lib/python3.9/site-packages/matplotlib/cbook/__init__.py", line 292, in process
    self.exception_handler(exc)
  File "/home/franzhd/anaconda3/envs/lava_new/lib/python3.9/site-packages/matplotlib/cbook/__init__.py", line 96, in _exception_printer
    raise exc
  File "/home/franzhd/anaconda3/envs/lava_new/lib/python3.9/site-packages/matplotlib/cbook/__init__.py", line 287, in process
    func(*args, **kwargs)
  File "/home/franzhd/anaconda3/envs/lava_new/lib/python3.9/site-packages/matplotlib/animation.py", line 911, in _start
    self.event_source.add_callback(self._step)
AttributeError: 'NoneType' object has no attribute 'add_callback'
Exception in Tkinter callback
Traceback (most recent call last):
  File "/home/franzhd/anaconda3/envs/lava_new/lib/python3.9/tkinter/__init__.py", line 1892, in __call__
    return self.func(*args)
  File "/home/franzhd/anaconda3/envs/lava_new/lib/python3.9/tkinter/__init__.py", line 814, in callit
    func(*args)
  File "/home/franzhd/anaconda3/envs/lava_new/lib/python3.9/site-packages/matplotlib/backends/_backend_tk.py", line 252, in idle_draw
    self.draw()
  File "/home/franzhd/anaconda3/envs/lava_new/lib/python3.9/site-packages/matplotlib/backends/backend_tkagg.py", line 9, in draw
    super().draw()
  File "/home/franzhd/anaconda3/envs/lava_new/lib/python3.9/site-packages/matplotlib/backends/backend_agg.py", line 436, in draw
    self.figure.draw(self.renderer)
  File "/home/franzhd/anaconda3/envs/lava_new/lib/python3.9/site-packages/matplotlib/artist.py", line 73, in draw_wrapper
    result = draw(artist, renderer, *args, **kwargs)
  File "/home/franzhd/anaconda3/envs/lava_new/lib/python3.9/site-packages/matplotlib/artist.py", line 50, in draw_wrapper
    return draw(artist, renderer)
  File "/home/franzhd/anaconda3/envs/lava_new/lib/python3.9/site-packages/matplotlib/figure.py", line 2847, in draw
    self.canvas.draw_event(renderer)
  File "/home/franzhd/anaconda3/envs/lava_new/lib/python3.9/site-packages/matplotlib/backend_bases.py", line 1779, in draw_event
    self.callbacks.process(s, event)
  File "/home/franzhd/anaconda3/envs/lava_new/lib/python3.9/site-packages/matplotlib/cbook/__init__.py", line 292, in process
    self.exception_handler(exc)
  File "/home/franzhd/anaconda3/envs/lava_new/lib/python3.9/site-packages/matplotlib/cbook/__init__.py", line 96, in _exception_printer
    raise exc
  File "/home/franzhd/anaconda3/envs/lava_new/lib/python3.9/site-packages/matplotlib/cbook/__init__.py", line 287, in process
    func(*args, **kwargs)
  File "/home/franzhd/anaconda3/envs/lava_new/lib/python3.9/site-packages/matplotlib/animation.py", line 911, in _start
    self.event_source.add_callback(self._step)
AttributeError: 'NoneType' object has no attribute 'add_callback'
Exception in Tkinter callback
Traceback (most recent call last):
  File "/home/franzhd/anaconda3/envs/lava_new/lib/python3.9/tkinter/__init__.py", line 1892, in __call__
    return self.func(*args)
  File "/home/franzhd/anaconda3/envs/lava_new/lib/python3.9/tkinter/__init__.py", line 814, in callit
    func(*args)
  File "/home/franzhd/anaconda3/envs/lava_new/lib/python3.9/site-packages/matplotlib/backends/_backend_tk.py", line 252, in idle_draw
    self.draw()
  File "/home/franzhd/anaconda3/envs/lava_new/lib/python3.9/site-packages/matplotlib/backends/backend_tkagg.py", line 9, in draw
    super().draw()
  File "/home/franzhd/anaconda3/envs/lava_new/lib/python3.9/site-packages/matplotlib/backends/backend_agg.py", line 436, in draw
    self.figure.draw(self.renderer)
  File "/home/franzhd/anaconda3/envs/lava_new/lib/python3.9/site-packages/matplotlib/artist.py", line 73, in draw_wrapper
    result = draw(artist, renderer, *args, **kwargs)
  File "/home/franzhd/anaconda3/envs/lava_new/lib/python3.9/site-packages/matplotlib/artist.py", line 50, in draw_wrapper
    return draw(artist, renderer)
  File "/home/franzhd/anaconda3/envs/lava_new/lib/python3.9/site-packages/matplotlib/figure.py", line 2847, in draw
    self.canvas.draw_event(renderer)
  File "/home/franzhd/anaconda3/envs/lava_new/lib/python3.9/site-packages/matplotlib/backend_bases.py", line 1779, in draw_event
    self.callbacks.process(s, event)
  File "/home/franzhd/anaconda3/envs/lava_new/lib/python3.9/site-packages/matplotlib/cbook/__init__.py", line 292, in process
    self.exception_handler(exc)
  File "/home/franzhd/anaconda3/envs/lava_new/lib/python3.9/site-packages/matplotlib/cbook/__init__.py", line 96, in _exception_printer
    raise exc
  File "/home/franzhd/anaconda3/envs/lava_new/lib/python3.9/site-packages/matplotlib/cbook/__init__.py", line 287, in process
    func(*args, **kwargs)
  File "/home/franzhd/anaconda3/envs/lava_new/lib/python3.9/site-packages/matplotlib/animation.py", line 911, in _start
    self.event_source.add_callback(self._step)
AttributeError: 'NoneType' object has no attribute 'add_callback'
Exception in Tkinter callback
Traceback (most recent call last):
  File "/home/franzhd/anaconda3/envs/lava_new/lib/python3.9/tkinter/__init__.py", line 1892, in __call__
    return self.func(*args)
  File "/home/franzhd/anaconda3/envs/lava_new/lib/python3.9/tkinter/__init__.py", line 814, in callit
    func(*args)
  File "/home/franzhd/anaconda3/envs/lava_new/lib/python3.9/site-packages/matplotlib/backends/_backend_tk.py", line 252, in idle_draw
    self.draw()
  File "/home/franzhd/anaconda3/envs/lava_new/lib/python3.9/site-packages/matplotlib/backends/backend_tkagg.py", line 9, in draw
    super().draw()
  File "/home/franzhd/anaconda3/envs/lava_new/lib/python3.9/site-packages/matplotlib/backends/backend_agg.py", line 436, in draw
    self.figure.draw(self.renderer)
  File "/home/franzhd/anaconda3/envs/lava_new/lib/python3.9/site-packages/matplotlib/artist.py", line 73, in draw_wrapper
    result = draw(artist, renderer, *args, **kwargs)
  File "/home/franzhd/anaconda3/envs/lava_new/lib/python3.9/site-packages/matplotlib/artist.py", line 50, in draw_wrapper
    return draw(artist, renderer)
  File "/home/franzhd/anaconda3/envs/lava_new/lib/python3.9/site-packages/matplotlib/figure.py", line 2847, in draw
    self.canvas.draw_event(renderer)
  File "/home/franzhd/anaconda3/envs/lava_new/lib/python3.9/site-packages/matplotlib/backend_bases.py", line 1779, in draw_event
    self.callbacks.process(s, event)
  File "/home/franzhd/anaconda3/envs/lava_new/lib/python3.9/site-packages/matplotlib/cbook/__init__.py", line 292, in process
    self.exception_handler(exc)
  File "/home/franzhd/anaconda3/envs/lava_new/lib/python3.9/site-packages/matplotlib/cbook/__init__.py", line 96, in _exception_printer
    raise exc
  File "/home/franzhd/anaconda3/envs/lava_new/lib/python3.9/site-packages/matplotlib/cbook/__init__.py", line 287, in process
    func(*args, **kwargs)
  File "/home/franzhd/anaconda3/envs/lava_new/lib/python3.9/site-packages/matplotlib/animation.py", line 911, in _start
    self.event_source.add_callback(self._step)
AttributeError: 'NoneType' object has no attribute 'add_callback'
Exception in Tkinter callback
Traceback (most recent call last):
  File "/home/franzhd/anaconda3/envs/lava_new/lib/python3.9/tkinter/__init__.py", line 1892, in __call__
    return self.func(*args)
  File "/home/franzhd/anaconda3/envs/lava_new/lib/python3.9/tkinter/__init__.py", line 814, in callit
    func(*args)
  File "/home/franzhd/anaconda3/envs/lava_new/lib/python3.9/site-packages/matplotlib/backends/_backend_tk.py", line 252, in idle_draw
    self.draw()
  File "/home/franzhd/anaconda3/envs/lava_new/lib/python3.9/site-packages/matplotlib/backends/backend_tkagg.py", line 9, in draw
    super().draw()
  File "/home/franzhd/anaconda3/envs/lava_new/lib/python3.9/site-packages/matplotlib/backends/backend_agg.py", line 436, in draw
    self.figure.draw(self.renderer)
  File "/home/franzhd/anaconda3/envs/lava_new/lib/python3.9/site-packages/matplotlib/artist.py", line 73, in draw_wrapper
    result = draw(artist, renderer, *args, **kwargs)
  File "/home/franzhd/anaconda3/envs/lava_new/lib/python3.9/site-packages/matplotlib/artist.py", line 50, in draw_wrapper
    return draw(artist, renderer)
  File "/home/franzhd/anaconda3/envs/lava_new/lib/python3.9/site-packages/matplotlib/figure.py", line 2847, in draw
    self.canvas.draw_event(renderer)
  File "/home/franzhd/anaconda3/envs/lava_new/lib/python3.9/site-packages/matplotlib/backend_bases.py", line 1779, in draw_event
    self.callbacks.process(s, event)
  File "/home/franzhd/anaconda3/envs/lava_new/lib/python3.9/site-packages/matplotlib/cbook/__init__.py", line 292, in process
    self.exception_handler(exc)
  File "/home/franzhd/anaconda3/envs/lava_new/lib/python3.9/site-packages/matplotlib/cbook/__init__.py", line 96, in _exception_printer
    raise exc
  File "/home/franzhd/anaconda3/envs/lava_new/lib/python3.9/site-packages/matplotlib/cbook/__init__.py", line 287, in process
    func(*args, **kwargs)
  File "/home/franzhd/anaconda3/envs/lava_new/lib/python3.9/site-packages/matplotlib/animation.py", line 911, in _start
    self.event_source.add_callback(self._step)
AttributeError: 'NoneType' object has no attribute 'add_callback'
Exception in Tkinter callback
Traceback (most recent call last):
  File "/home/franzhd/anaconda3/envs/lava_new/lib/python3.9/tkinter/__init__.py", line 1892, in __call__
    return self.func(*args)
  File "/home/franzhd/anaconda3/envs/lava_new/lib/python3.9/tkinter/__init__.py", line 814, in callit
    func(*args)
  File "/home/franzhd/anaconda3/envs/lava_new/lib/python3.9/site-packages/matplotlib/backends/_backend_tk.py", line 252, in idle_draw
    self.draw()
  File "/home/franzhd/anaconda3/envs/lava_new/lib/python3.9/site-packages/matplotlib/backends/backend_tkagg.py", line 9, in draw
    super().draw()
  File "/home/franzhd/anaconda3/envs/lava_new/lib/python3.9/site-packages/matplotlib/backends/backend_agg.py", line 436, in draw
    self.figure.draw(self.renderer)
  File "/home/franzhd/anaconda3/envs/lava_new/lib/python3.9/site-packages/matplotlib/artist.py", line 73, in draw_wrapper
    result = draw(artist, renderer, *args, **kwargs)
  File "/home/franzhd/anaconda3/envs/lava_new/lib/python3.9/site-packages/matplotlib/artist.py", line 50, in draw_wrapper
    return draw(artist, renderer)
  File "/home/franzhd/anaconda3/envs/lava_new/lib/python3.9/site-packages/matplotlib/figure.py", line 2847, in draw
    self.canvas.draw_event(renderer)
  File "/home/franzhd/anaconda3/envs/lava_new/lib/python3.9/site-packages/matplotlib/backend_bases.py", line 1779, in draw_event
    self.callbacks.process(s, event)
  File "/home/franzhd/anaconda3/envs/lava_new/lib/python3.9/site-packages/matplotlib/cbook/__init__.py", line 292, in process
    self.exception_handler(exc)
  File "/home/franzhd/anaconda3/envs/lava_new/lib/python3.9/site-packages/matplotlib/cbook/__init__.py", line 96, in _exception_printer
    raise exc
  File "/home/franzhd/anaconda3/envs/lava_new/lib/python3.9/site-packages/matplotlib/cbook/__init__.py", line 287, in process
    func(*args, **kwargs)
  File "/home/franzhd/anaconda3/envs/lava_new/lib/python3.9/site-packages/matplotlib/animation.py", line 911, in _start
    self.event_source.add_callback(self._step)
AttributeError: 'NoneType' object has no attribute 'add_callback'
Exception in Tkinter callback
Traceback (most recent call last):
  File "/home/franzhd/anaconda3/envs/lava_new/lib/python3.9/tkinter/__init__.py", line 1892, in __call__
    return self.func(*args)
  File "/home/franzhd/anaconda3/envs/lava_new/lib/python3.9/tkinter/__init__.py", line 814, in callit
    func(*args)
  File "/home/franzhd/anaconda3/envs/lava_new/lib/python3.9/site-packages/matplotlib/backends/_backend_tk.py", line 252, in idle_draw
    self.draw()
  File "/home/franzhd/anaconda3/envs/lava_new/lib/python3.9/site-packages/matplotlib/backends/backend_tkagg.py", line 9, in draw
    super().draw()
  File "/home/franzhd/anaconda3/envs/lava_new/lib/python3.9/site-packages/matplotlib/backends/backend_agg.py", line 436, in draw
    self.figure.draw(self.renderer)
  File "/home/franzhd/anaconda3/envs/lava_new/lib/python3.9/site-packages/matplotlib/artist.py", line 73, in draw_wrapper
    result = draw(artist, renderer, *args, **kwargs)
  File "/home/franzhd/anaconda3/envs/lava_new/lib/python3.9/site-packages/matplotlib/artist.py", line 50, in draw_wrapper
    return draw(artist, renderer)
  File "/home/franzhd/anaconda3/envs/lava_new/lib/python3.9/site-packages/matplotlib/figure.py", line 2847, in draw
    self.canvas.draw_event(renderer)
  File "/home/franzhd/anaconda3/envs/lava_new/lib/python3.9/site-packages/matplotlib/backend_bases.py", line 1779, in draw_event
    self.callbacks.process(s, event)
  File "/home/franzhd/anaconda3/envs/lava_new/lib/python3.9/site-packages/matplotlib/cbook/__init__.py", line 292, in process
    self.exception_handler(exc)
  File "/home/franzhd/anaconda3/envs/lava_new/lib/python3.9/site-packages/matplotlib/cbook/__init__.py", line 96, in _exception_printer
    raise exc
  File "/home/franzhd/anaconda3/envs/lava_new/lib/python3.9/site-packages/matplotlib/cbook/__init__.py", line 287, in process
    func(*args, **kwargs)
  File "/home/franzhd/anaconda3/envs/lava_new/lib/python3.9/site-packages/matplotlib/animation.py", line 911, in _start
    self.event_source.add_callback(self._step)
AttributeError: 'NoneType' object has no attribute 'add_callback'
